Workbook

Sheet Summary
A1: MCP 2026-15 Market Research: Rotary-Wing Aircraft SIN
A2: Federal contract data FY2016-FY2026 (USAspending) and contract sales FY2020-FY2026 Q2 (SSQ+). Prepared Oct 2026. Every number below is a formula over the data tabs.
A4: Bottom line
A5: Helicopters never left MAS. CBP has bought every Light Enforcement Helicopter since 2018 through GS-07F-139DA, state and local buyers account for a fifth or more of the contract's sales, and the aircraft have been sold under SINs not written for them, including after Refresh 26 excluded them. A dedicated SIN is the right fix, on three conditions: configured aircraft in scope, Cooperative Purchasing eligibility, and a second manufacturer (realistically a Bell dealer).
A7: Key number | B7: Value | C7: Basis
A8: Civilian helicopter purchases, FY2016-FY2026 | B8: =Purchases!H25 -> 509551000 | C8: 20 awards, 11 buying organizations; complete aircraft only
A9: Average purchases per year | B9: ='Annual Trends'!B17 -> 46322818 | C9: Median is nearly identical; three years had no purchases
A10: CBP share of purchase dollars | B10: =SUMIFS(Purchases!$H$5:$H$24,Purchases!$B$5:$B$24,"CBP")/Purchases!H25 -> 0.63398953 | C10: The draft's 'about 70 percent' holds on aircraft, not dollars
A11: CBP share of aircraft (known counts) | B11: =SUMIFS(Purchases!$G$5:$G$24,Purchases!$B$5:$B$24,"CBP")/Purchases!G25 -> 0.7 | C11: 42 of 60 aircraft whose counts FPDS states
A12: Share of purchase dollars through MAS | B12: =SUMIFS(Purchases!$H$5:$H$24,Purchases!$C$5:$C$24,"GSA MAS")/Purchases!H25 -> 0.67961794 | C12: All of it one dealer, Davenport Aviation (Airbus)
A13: CBP aircraft ordered on MAS since 2018 | B13: ='CBP Orders'!C31 -> 42 | C13: Five orders; every CBP helicopter purchase in the period
A14: CBP price per aircraft, first order (Jul 2018) | B14: ='CBP Orders'!F24 -> 6565504.7 | C14: Configured H125
A15: CBP price per aircraft, latest order (May 2026) | B15: ='CBP Orders'!F29 -> 9550781.4 | C15: About 5% a year; crosses the proposed $10M maximum order on the next buy
A16: Configuration share of price | B16: ='CBP Orders'!G36 -> 0.33701424 | C16: Lightly equipped FWS H125 vs. CBP configured H125, 2022. Includes third-party FLIR and Troll equipment
A17: Offers on CBP's five MAS orders | B17: 1, 1, 1, 1, 2 | C17: Brand-name, small-business set-aside; the May 2026 order drew two
A18: Bell share of non-CBP purchases | B18: =SUMIFS(Purchases!$H$5:$H$24,Purchases!$D$5:$D$24,"Bell Textron",Purchases!$B$5:$B$24,"<>CBP")/SUMIFS(Purchases!$H$5:$H$24,Purchases!$B$5:$B$24,"<>CBP") -> 0.61303157 | C18: All off-schedule: FBI and DEA IDIQs, Park Police open market (not competed)
A19: Contract sales, FY2020-FY2026 Q2 | B19: ='Contract Sales'!L16 -> 293931153 | C19: SSQ+, all SINs, GS-07F-139DA
A20: State/local share of contract sales (low reading) | B20: ='Contract Sales'!I32 -> 0.21575237 | C20: Treats FY2025-26 state/local sales as misreported CBP deliveries
A21: State/local share of contract sales (as reported) | B21: ='Contract Sales'!I31 -> 0.38320782 | C21: Either reading contradicts GSS's 'limited'
A22: Sales on SIN 336413 after the Refresh 26 exclusion | B22: ='Contract Sales'!I27 -> 39276140 | C22: Plus CBP orders of $17.6M (Sep 2025) and $95.5M (May 2026)
A23: IFF actually collected on contract sales | B23: ='Annual Trends'!K16 -> 2204483.6 | C23: 0.75% of SSQ+ sales, FY2020-FY2026 Q2
A24: Civilian adjacent spend (parts, repair, services) | B24: ='Adjacent Spend'!G9 -> 1.0928512e+09 | C24: Floor; Coast Guard is 97% of parts
A25: Purchases as share of civilian rotary-wing contract spend | B25: ='Adjacent Spend'!G11 -> 0.31799195 | C25: A purchase SIN reaches about a third at most
A26: Projected volume, year 1 / year 5 | B26: =Projection!F16 -> 44243505 | C26: Year 5 in the next row; change package projects $50M rising to $103M
B27: =Projection!F20 -> 57989470 | C27: Year 5 with a Bell dealer from year 3
A28: Projected IFF, year 1 / year 5 | B28: =Projection!G16 -> 331826.29
B29: =Projection!G20 -> 434921.03
A31: Key findings
A32: 1. CBP has bought every Light Enforcement Helicopter since 2018 on GS-07F-139DA: five orders, 42 aircraft. GSS recommended moving off MAS a customer that had used nothing else for seven years, and CBP placed another order the same month.
A33: 2. The 70% CBP figure holds on aircraft counts (70%) and nearly on dollars (63%). Say 'about two-thirds.'
A34: 3. State and local demand is not limited: 22-38% of the contract's sales, $10M-$17M a year. The channel began in 2017 at state and local request.
A35: 4. The aircraft have never had a SIN written for them: sales ran under legacy 567-99, SIN 332216 (law enforcement tools), and SIN 336413, including $39M after Refresh 26 excluded complete aircraft. The authorizing document for the temporary accommodation was not located.
A36: 5. Configuration is about a third of CBP's price and includes third-party equipment (FLIR, Troll). A Phase 1 SIN without mission-system integration cannot carry CBP's next order.
A37: 6. Outside CBP, Bell won 61% of civilian purchases, all off-schedule. Growth beyond CBP depends on a Bell dealer joining the SIN.
A38: 7. Federal civilian demand is about $46M a year, half the change package's $100M assumption. Actual contract sales of ~$45M a year support the package's year-1 figure but not growth to $103M.
A39: 8. No evidence that open-market buying would beat MAS for CBP: no open-market configured H125 exists to compare, and the latest MAS order drew two bids.
A41: Recommendation
A42: Establish the dedicated SIN (Alternative C), conditioned on:
A43: a. Dealer-installed mission equipment delivered with the aircraft in Phase 1 scope, priced as listed options.
... A53: Tabs
...

Sheet Annual Trends
A1: Annual trends, FY2016-FY2026
A2: Purchases by award year (Purchases tab). MAS obligations by obligation year (FPDS). Contract sales by report year (SSQ+). FY2026 is incomplete in FPDS and SSQ+.
A4: FY | B4: Civilian purchases | C4: CBP | D4: Other agencies | E4: CBP share | F4: Aircraft (known counts) | G4: MAS obligations, civilian (FPDS) | H4: Contract sales, federal (SSQ+) | I4: Contract sales, state/local | J4: Contract sales, total | K4: IFF on contract sales | L4: Adjacent civilian spend
A5: 2016 | B5: =SUMIFS(Purchases!$H$5:$H$24,Purchases!$A$5:$A$24,A5) -> 9233000 | C5: =SUMIFS(Purchases!$H$5:$H$24,Purchases!$A$5:$A$24,A5,Purchases!$B$5:$B$24,"CBP") -> 0 | D5: =B5-C5 -> 9233000 | E5: =IF(B5>0,C5/B5,"") -> 0 | F5: =SUMIFS(Purchases!$G$5:$G$24,Purchases!$A$5:$A$24,A5) -> 1 | G5: 0 | H5: =SUMIFS('Contract Sales'!$I$6:$I$15,'Contract Sales'!$H$6:$H$15,A5) -> 0 | I5: =SUMIFS('Contract Sales'!$J$6:$J$15,'Contract Sales'!$H$6:$H$15,A5) -> 0 | J5: =SUMIFS('Contract Sales'!$L$6:$L$15,'Contract Sales'!$H$6:$H$15,A5) -> 0 | K5: =J5*Projection!$C$9 -> 0 | L5: =SUMIFS('Adjacent Spend'!$D$5:$D$86,'Adjacent Spend'!$A$5:$A$86,"Civilian",'Adjacent Spend'!$C$5:$C$86,A5) -> 40671275
A6: 2017 | B6: =SUMIFS(Purchases!$H$5:$H$24,Purchases!$A$5:$A$24,A6) -> 0 | C6: =SUMIFS(Purchases!$H$5:$H$24,Purchases!$A$5:$A$24,A6,Purchases!$B$5:$B$24,"CBP") -> 0 | D6: =B6-C6 -> 0 | E6: =IF(B6>0,C6/B6,"") | F6: =SUMIFS(Purchases!$G$5:$G$24,Purchases!$A$5:$A$24,A6) -> 0 | G6: 0 | H6: =SUMIFS('Contract Sales'!$I$6:$I$15,'Contract Sales'!$H$6:$H$15,A6) -> 0 | I6: =SUMIFS('Contract Sales'!$J$6:$J$15,'Contract Sales'!$H$6:$H$15,A6) -> 0 | J6: =SUMIFS('Contract Sales'!$L$6:$L$15,'Contract Sales'!$H$6:$H$15,A6) -> 0 | K6: =J6*Projection!$C$9 -> 0 | L6: =SUMIFS('Adjacent Spend'!$D$5:$D$86,'Adjacent Spend'!$A$5:$A$86,"Civilian",'Adjacent Spend'!$C$5:$C$86,A6) -> 60433531
A7: 2018 | B7: =SUMIFS(Purchases!$H$5:$H$24,Purchases!$A$5:$A$24,A7) -> 73197000 | C7: =SUMIFS(Purchases!$H$5:$H$24,Purchases!$A$5:$A$24,A7,Purchases!$B$5:$B$24,"CBP") -> 45960000 | D7: =B7-C7 -> 27237000 | E7: =IF(B7>0,C7/B7,"") -> 0.62789459 | F7: =SUMIFS(Purchases!$G$5:$G$24,Purchases!$A$5:$A$24,A7) -> 11 | G7: 45958533 | H7: =SUMIFS('Contract Sales'!$I$6:$I$15,'Contract Sales'!$H$6:$H$15,A7) -> 0 | I7: =SUMIFS('Contract Sales'!$J$6:$J$15,'Contract Sales'!$H$6:$H$15,A7) -> 0 | J7: =SUMIFS('Contract Sales'!$L$6:$L$15,'Contract Sales'!$H$6:$H$15,A7) -> 0 | K7: =J7*Projection!$C$9 -> 0 | L7: =SUMIFS('Adjacent Spend'!$D$5:$D$86,'Adjacent Spend'!$A$5:$A$86,"Civilian",'Adjacent Spend'!$C$5:$C$86,A7) -> 63896466
A8: 2019 | B8: =SUMIFS(Purchases!$H$5:$H$24,Purchases!$A$5:$A$24,A8) -> 92301000 | C8: =SUMIFS(Purchases!$H$5:$H$24,Purchases!$A$5:$A$24,A8,Purchases!$B$5:$B$24,"CBP") -> 65720000 | D8: =B8-C8 -> 26581000 | E8: =IF(B8>0,C8/B8,"") -> 0.71201829 | F8: =SUMIFS(Purchases!$G$5:$G$24,Purchases!$A$5:$A$24,A8) -> 14 | G8: 77413529 | H8: =SUMIFS('Contract Sales'!$I$6:$I$15,'Contract Sales'!$H$6:$H$15,A8) -> 0 | I8: =SUMIFS('Contract Sales'!$J$6:$J$15,'Contract Sales'!$H$6:$H$15,A8) -> 0 | J8: =SUMIFS('Contract Sales'!$L$6:$L$15,'Contract Sales'!$H$6:$H$15,A8) -> 0 | K8: =J8*Projection!$C$9 -> 0 | L8: =SUMIFS('Adjacent Spend'!$D$5:$D$86,'Adjacent Spend'!$A$5:$A$86,"Civilian",'Adjacent Spend'!$C$5:$C$86,A8) -> 92221156
A9: 2020 | B9: =SUMIFS(Purchases!$H$5:$H$24,Purchases!$A$5:$A$24,A9) -> 0 | C9: =SUMIFS(Purchases!$H$5:$H$24,Purchases!$A$5:$A$24,A9,Purchases!$B$5:$B$24,"CBP") -> 0 | D9: =B9-C9 -> 0 | E9: =IF(B9>0,C9/B9,"") | F9: =SUMIFS(Purchases!$G$5:$G$24,Purchases!$A$5:$A$24,A9) -> 0 | G9: 6649394.4 | H9: =SUMIFS('Contract Sales'!$I$6:$I$15,'Contract Sales'!$H$6:$H$15,A9) -> 26056656 | I9: =SUMIFS('Contract Sales'!$J$6:$J$15,'Contract Sales'!$H$6:$H$15,A9) -> 8160589 | J9: =SUMIFS('Contract Sales'!$L$6:$L$15,'Contract Sales'!$H$6:$H$15,A9) -> 34217245 | K9: =J9*Projection!$C$9 -> 256629.34 | L9: =SUMIFS('Adjacent Spend'!$D$5:$D$86,'Adjacent Spend'!$A$5:$A$86,"Civilian",'Adjacent Spend'!$C$5:$C$86,A9) -> 93168006
A10: 2021 | B10: =SUMIFS(Purchases!$H$5:$H$24,Purchases!$A$5:$A$24,A10) -> 85808000 | C10: =SUMIFS(Purchases!$H$5:$H$24,Purchases!$A$5:$A$24,A10,Purchases!$B$5:$B$24,"CBP") -> 63590000 | D10: =B10-C10 -> 22218000 | E10: =IF(B10>0,C10/B10,"") -> 0.74107309 | F10: =SUMIFS(Purchases!$G$5:$G$24,Purchases!$A$5:$A$24,A10) -> 13 | G10: 49414873 | H10: =SUMIFS('Contract Sales'!$I$6:$I$15,'Contract Sales'!$H$6:$H$15,A10) -> 66255243 | I10: =SUMIFS('Contract Sales'!$J$6:$J$15,'Contract Sales'!$H$6:$H$15,A10) -> 10417913 | J10: =SUMIFS('Contract Sales'!$L$6:$L$15,'Contract Sales'!$H$6:$H$15,A10) -> 76673156 | K10: =J10*Projection!$C$9 -> 575048.67 | L10: =SUMIFS('Adjacent Spend'!$D$5:$D$86,'Adjacent Spend'!$A$5:$A$86,"Civilian",'Adjacent Spend'!$C$5:$C$86,A10) -> 1.9174291e+08
A11: 2022 | B11: =SUMIFS(Purchases!$H$5:$H$24,Purchases!$A$5:$A$24,A11) -> 45142000 | C11: =SUMIFS(Purchases!$H$5:$H$24,Purchases!$A$5:$A$24,A11,Purchases!$B$5:$B$24,"CBP") -> 0 | D11: =B11-C11 -> 45142000 | E11: =IF(B11>0,C11/B11,"") -> 0 | F11: =SUMIFS(Purchases!$G$5:$G$24,Purchases!$A$5:$A$24,A11) -> 4 | G11: 19307590 | H11: =SUMIFS('Contract Sales'!$I$6:$I$15,'Contract Sales'!$H$6:$H$15,A11) -> 16304729 | I11: =SUMIFS('Contract Sales'!$J$6:$J$15,'Contract Sales'!$H$6:$H$15,A11) -> 0 | J11: =SUMIFS('Contract Sales'!$L$6:$L$15,'Contract Sales'!$H$6:$H$15,A11) -> 22653101 | K11: =J11*Projection!$C$9 -> 169898.26 | L11: =SUMIFS('Adjacent Spend'!$D$5:$D$86,'Adjacent Spend'!$A$5:$A$86,"Civilian",'Adjacent Spend'!$C$5:$C$86,A11) -> 90439443
A12: 2023 | B12: =SUMIFS(Purchases!$H$5:$H$24,Purchases!$A$5:$A$24,A12) -> 52270000 | C12: =SUMIFS(Purchases!$H$5:$H$24,Purchases!$A$5:$A$24,A12,Purchases!$B$5:$B$24,"CBP") -> 52270000 | D12: =B12-C12 -> 0 | E12: =IF(B12>0,C12/B12,"") -> 1 | F12: =SUMIFS(Purchases!$G$5:$G$24,Purchases!$A$5:$A$24,A12) -> 6 | G12: 9523159.8 | H12: =SUMIFS('Contract Sales'!$I$6:$I$15,'Contract Sales'!$H$6:$H$15,A12) -> 53148289 | I12: =SUMIFS('Contract Sales'!$J$6:$J$15,'Contract Sales'!$H$6:$H$15,A12) -> 22683187 | J12: =SUMIFS('Contract Sales'!$L$6:$L$15,'Contract Sales'!$H$6:$H$15,A12) -> 75831476 | K12: =J12*Projection!$C$9 -> 568736.07 | L12: =SUMIFS('Adjacent Spend'!$D$5:$D$86,'Adjacent Spend'!$A$5:$A$86,"Civilian",'Adjacent Spend'!$C$5:$C$86,A12) -> 1.1606803e+08
A13: 2024 | B13: =SUMIFS(Purchases!$H$5:$H$24,Purchases!$A$5:$A$24,A13) -> 2850000 | C13: =SUMIFS(Purchases!$H$5:$H$24,Purchases!$A$5:$A$24,A13,Purchases!$B$5:$B$24,"CBP") -> 0 | D13: =B13-C13 -> 2850000 | E13: =IF(B13>0,C13/B13,"") -> 0 | F13: =SUMIFS(Purchases!$G$5:$G$24,Purchases!$A$5:$A$24,A13) -> 1 | G13: 24630323 | H13: =SUMIFS('Contract Sales'!$I$6:$I$15,'Contract Sales'!$H$6:$H$15,A13) -> 12296946 | I13: =SUMIFS('Contract Sales'!$J$6:$J$15,'Contract Sales'!$H$6:$H$15,A13) -> 22154653 | J13: =SUMIFS('Contract Sales'!$L$6:$L$15,'Contract Sales'!$H$6:$H$15,A13) -> 34451599 | K13: =J13*Projection!$C$9 -> 258386.99 | L13: =SUMIFS('Adjacent Spend'!$D$5:$D$86,'Adjacent Spend'!$A$5:$A$86,"Civilian",'Adjacent Spend'!$C$5:$C$86,A13) -> 1.0818826e+08
A14: 2025 | B14: =SUMIFS(Purchases!$H$5:$H$24,Purchases!$A$5:$A$24,A14) -> 0 | C14: =SUMIFS(Purchases!$H$5:$H$24,Purchases!$A$5:$A$24,A14,Purchases!$B$5:$B$24,"CBP") -> 0 | D14: =B14-C14 -> 0 | E14: =IF(B14>0,C14/B14,"") | F14: =SUMIFS(Purchases!$G$5:$G$24,Purchases!$A$5:$A$24,A14) -> 0 | G14: 19828717 | H14: =SUMIFS('Contract Sales'!$I$6:$I$15,'Contract Sales'!$H$6:$H$15,A14) -> 884201 | I14: =SUMIFS('Contract Sales'!$J$6:$J$15,'Contract Sales'!$H$6:$H$15,A14) -> 10450824 | J14: =SUMIFS('Contract Sales'!$L$6:$L$15,'Contract Sales'!$H$6:$H$15,A14) -> 11335025 | K14: =J14*Projection!$C$9 -> 85012.688 | L14: =SUMIFS('Adjacent Spend'!$D$5:$D$86,'Adjacent Spend'!$A$5:$A$86,"Civilian",'Adjacent Spend'!$C$5:$C$86,A14) -> 1.050666e+08
A15: 2026 | B15: =SUMIFS(Purchases!$H$5:$H$24,Purchases!$A$5:$A$24,A15) -> 148750000 | C15: =SUMIFS(Purchases!$H$5:$H$24,Purchases!$A$5:$A$24,A15,Purchases!$B$5:$B$24,"CBP") -> 95510000 | D15: =B15-C15 -> 53240000 | E15: =IF(B15>0,C15/B15,"") -> 0.64208403 | F15: =SUMIFS(Purchases!$G$5:$G$24,Purchases!$A$5:$A$24,A15) -> 10 | G15: 98616814 | H15: =SUMIFS('Contract Sales'!$I$6:$I$15,'Contract Sales'!$H$6:$H$15,A15) -> 0 | I15: =SUMIFS('Contract Sales'!$J$6:$J$15,'Contract Sales'!$H$6:$H$15,A15) -> 38769551 | J15: =SUMIFS('Contract Sales'!$L$6:$L$15,'Contract Sales'!$H$6:$H$15,A15) -> 38769551 | K15: =J15*Projection!$C$9 -> 290771.63 | L15: =SUMIFS('Adjacent Spend'!$D$5:$D$86,'Adjacent Spend'!$A$5:$A$86,"Civilian",'Adjacent Spend'!$C$5:$C$86,A15) -> 1.3095551e+08
A16: Total | B16: =SUM(B5:B15) -> 509551000 | C16: =SUM(C5:C15) -> 323050000 | D16: =SUM(D5:D15) -> 186501000 | E16: =C16/B16 -> 0.63398953 | F16: =SUM(F5:F15) -> 60 | G16: =SUM(G5:G15) -> 3.5134293e+08 | H16: =SUM(H5:H15) -> 174946064 | I16: =SUM(I5:I15) -> 112636717 | J16: =SUM(J5:J15) -> 293931153 | K16: =SUM(K5:K15) -> 2204483.6 | L16: =SUM(L5:L15) -> 1.0928512e+09
A17: Mean | B17: =AVERAGE(B5:B15) -> 46322818 | G17: =AVERAGE(G5:G15) -> 31940267
A18: Median | B18: =MEDIAN(B5:B15) -> 45142000 | G18: =MEDIAN(G5:G15) -> 19828717
A20: Column G is hard-coded from analyze.py output (by_vehicle.csv, civilian GSA MAS row); it includes CBP simulators. Contract sales start in FY2020; FY2017-FY2019 had none reported.
A21: Purchases and contract sales measure different events (order vs delivery) and do not reconcile by year.

Sheet Purchases
A1: Civilian helicopter purchases, FY2016-FY2026
A2: Complete aircraft only. Sustainment, parts, overhaul, and the Coast Guard H-60 hull rebuild excluded. Hand-tagged from FPDS award descriptions.
A4: FY | B4: Customer | C4: Vehicle | D4: Vendor | E4: Model | F4: New/used | G4: Aircraft | H4: Obligations | I4: Per aircraft | J4: Offers | K4: Extent competed | L4: CBP? | M4: Count basis | N4: FPDS award
A5: 2016 | B5: NPS | C5: Open market | D5: Rainier Heli International | E5: Bell 412EP | F5: used | G5: 1 | H5: 4633000 | I5: =IF(G5>0,H5/G5,"") -> 4633000 | J5: 4 | K5: A | L5: =IF(B5="CBP","Yes","No") -> No | M5: description | N5: CONT_AWD_IND16PC00153_1406_-NONE-_-NONE-
A6: 2016 | B6: USDA APHIS | C6: Open market | D6: Shier Aviation | E6: unspecified | F6: unknown | H6: 4600000 | I6: =IF(G6>0,H6/G6,"") | J6: 3 | K6: F | L6: =IF(B6="CBP","Yes","No") -> No | M6: unknown; description says helicopters | N6: CONT_AWD_AG6395C160206_12K3_-NONE-_-NONE-
A7: 2018 | B7: CBP | C7: GSA MAS | D7: Davenport Aviation | E7: H125 LEH | F7: new | G7: 7 | H7: 45960000 | I7: =IF(G7>0,H7/G7,"") -> 6565714.3 | J7: 1 | K7: A | L7: =IF(B7="CBP","Yes","No") -> Yes | M7: press ($45.9M for 7) | N7: CONT_AWD_70B02C18F00000452_7014_GS07F139DA_4732
A8: 2018 | B8: FBI | C8: Agency IDV | D8: Bell Textron | E8: Bell 429 | F8: new | G8: 3 | H8: 18122000 | I8: =IF(G8>0,H8/G8,"") -> 6040666.7 | K8: F | L8: =IF(B8="CBP","Yes","No") -> No | M8: one order per aircraft | N8: 15F06718F0001311 / 1352 / 1354 under 15F06718D0004181
A9: 2018 | B9: DEA | C9: Open market | D9: Bell Textron | E9: Bell 407 | F9: used | H9: 6820000 | I9: =IF(G9>0,H9/G9,"") | J9: 1 | K9: D | L9: =IF(B9="CBP","Yes","No") -> No | M9: unknown; description says helicopters | N9: CONT_AWD_15DDHQ18P00000696_1524_-NONE-_-NONE-
A10: 2018 | B10: DOE WAPA | C10: Open market | D10: Bell Textron | E10: Bell 407 | F10: used | G10: 1 | H10: 2295000 | I10: =IF(G10>0,H10/G10,"") -> 2295000 | J10: 4 | K10: F | L10: =IF(B10="CBP","Yes","No") -> No | M10: description | N10: CONT_AWD_89503018CWA000001_8900_-NONE-_-NONE-
A11: 2019 | B11: CBP | C11: GSA MAS | D11: Davenport Aviation | E11: H125 LEH | F11: new | G11: 10 | H11: 65720000 | I11: =IF(G11>0,H11/G11,"") -> 6572000 | J11: 1 | K11: A | L11: =IF(B11="CBP","Yes","No") -> Yes | M11: 9 + option for 10th exercised; matches press $65.7M | N11: CONT_AWD_70B02C19F00000617_7014_GS07F139DA_4732
A12: 2019 | B12: NASA | C12: GSA MAS | D12: Davenport Aviation | E12: H135 T3/P | F12: new | G12: 3 | H12: 18480000 | I12: =IF(G12>0,H12/G12,"") -> 6160000 | J12: 1 | K12: A | L12: =IF(B12="CBP","Yes","No") -> No | M12: description (three) | N12: NASA order under GS07F139DA
A13: 2019 | B13: DEA | C13: Agency IDV | D13: Bell Textron | E13: Bell 407GXi | F13: new | G13: 1 | H13: 8101000 | I13: =IF(G13>0,H13/G13,"") -> 8101000 | K13: A | L13: =IF(B13="CBP","Yes","No") -> No | M13: description | N13: CONT_AWD_15DDHQ19F00001759_1524_15DDHQ19D00000023_1524
A14: 2021 | B14: CBP | C14: GSA MAS | D14: Davenport Aviation | E14: H125 LEH | F14: new | G14: 9 | H14: 63590000 | I14: =IF(G14>0,H14/G14,"") -> 7065555.6 | J14: 1 | K14: A | L14: =IF(B14="CBP","Yes","No") -> Yes | M14: 3 initial ($21.2M press) + LEH 4-7 + 2 more | N14: CONT_AWD_70B02C21F00000080_7014_GS07F139DA_4732
A15: 2021 | B15: FBI | C15: Agency IDV | D15: Bell Textron | E15: Bell 429 | F15: new | G15: 2 | H15: 17810000 | I15: =IF(G15>0,H15/G15,"") -> 8905000 | K15: F | L15: =IF(B15="CBP","Yes","No") -> No | M15: one order per aircraft | N15: 15F06721F0002394 / 3007 under 15F06718D0004181
A16: 2021 | B16: DOE WAPA | C16: Open market | D16: Bell Textron | E16: Bell 407GXi | F16: new | G16: 1 | H16: 3577000 | I16: =IF(G16>0,H16/G16,"") -> 3577000 | J16: 1 | K16: G | L16: =IF(B16="CBP","Yes","No") -> No | M16: description | N16: CONT_AWD_89503021CWA000011_8900_-NONE-_-NONE-
A17: 2021 | B17: State INL | C17: Open market | D17: unknown | E17: Bell 206B3 | F17: used | G17: 1 | H17: 831000 | I17: =IF(G17>0,H17/G17,"") -> 831000 | J17: 9 | K17: F | L17: =IF(B17="CBP","Yes","No") -> No | M17: description | N17: CONT_AWD_19AQMM21P0763_1900_-NONE-_-NONE-
A18: 2022 | B18: DOI FWS | C18: GSA MAS | D18: Davenport Aviation | E18: H125 | F18: new | G18: 1 | H18: 4770000 | I18: =IF(G18>0,H18/G18,"") -> 4770000 | J18: 1 | K18: A | L18: =IF(B18="CBP","Yes","No") -> No | M18: description; bare or lightly equipped aircraft | N18: FWS order under GS07F139DA
A19: 2022 | B19: DOE NNSA | C19: Open market | D19: Leonardo Helicopters | E19: unspecified twin | F19: new | G19: 2 | H19: 36006000 | I19: =IF(G19>0,H19/G19,"") -> 18003000 | J19: 4 | K19: A | L19: =IF(B19="CBP","Yes","No") -> No | M19: description (two) | N19: CONT_AWD_89233122CNA000245_8900_-NONE-_-NONE-
A20: 2022 | B20: DEA | C20: Agency IDV | D20: Bell Textron | E20: Bell single-engine light utility | F20: new | G20: 1 | H20: 4366000 | I20: =IF(G20>0,H20/G20,"") -> 4366000 | K20: A | L20: =IF(B20="CBP","Yes","No") -> No | M20: description | N20: CONT_AWD_15DDHQ22F00000733_1524_15DDHQ19D00000023_1524
A21: 2023 | B21: CBP | C21: GSA MAS | D21: Davenport Aviation | E21: H125 LEP | F21: new | G21: 6 | H21: 52270000 | I21: =IF(G21>0,H21/G21,"") -> 8711666.7 | J21: 1 | K21: A | L21: =IF(B21="CBP","Yes","No") -> Yes | M21: Davenport file: 1 at base (Sep 2023) + 3 (P00002 Aug 2024) + 2 (P00004 Sep 2025); includes $0.35M FLIR and switch upgrades | N21: CONT_AWD_70B02C23F00000959_7014_GS07F139DA_4732
A22: 2024 | B22: USDA APHIS | C22: Open market | D22: Trinity Aviation | E22: MD 530F | F22: unknown | G22: 1 | H22: 2850000 | I22: =IF(G22>0,H22/G22,"") -> 2850000 | J22: 2 | K22: F | L22: =IF(B22="CBP","Yes","No") -> No | M22: description | N22: CONT_AWD_12639524P0191_12K3_-NONE-_-NONE-
A23: 2026 | B23: CBP | C23: GSA MAS | D23: Davenport Aviation | E23: H125 LEP RW | F23: new | G23: 10 | H23: 95510000 | I23: =IF(G23>0,H23/G23,"") -> 9551000 | J23: 2 | K23: A | L23: =IF(B23="CBP","Yes","No") -> Yes | M23: description (quantity 10) | N23: CONT_AWD_70B02C26F00000290_7014_GS07F139DA_4732
A24: 2026 | B24: DOI US Park Police | C24: Open market | D24: Bell Textron | E24: unspecified | F24: new | H24: 53240000 | I24: =IF(G24>0,H24/G24,"") | J24: 1 | K24: C | L24: =IF(B24="CBP","Yes","No") -> No | M24: unknown; not competed | N24: CONT_AWD_140D0426C0109_1406_-NONE-_-NONE-
A25: Total | G25: =SUM(G5:G24) -> 60 | H25: =SUM(H5:H24) -> 509551000
A27: Blank aircraft counts: FPDS description does not state a count (APHIS FY2016, DEA used 407s, U.S. Park Police). Per-aircraft price shown only where the count is known.
A28: Source: USAspending prime award transactions, pulled Oct 19, 2026; civilian_aircraft_purchases.csv.

Sheet CBP Orders
A1: CBP Light Enforcement Helicopter orders on GS-07F-139DA (Davenport Aviation)
A2: Every action that ordered aircraft, plus configuration upgrades and simulators. Blue = hand-entered from mod text.
A4: Order | B4: Mod | C4: Action date | D4: FY | E4: Description | F4: Aircraft added | G4: Obligation | H4: Per aircraft | I4: Offers on order | J4: Fair opportunity code | K4: Aircraft count basis
A5: 70B02C18F00000452 | B5: 0 | C5: 43299 | D5: 2018 | E5: LIGHT ENFORCEMENT HELICOPTERS | F5: 7 | G5: 45958533 | H5: =IF(F5>0,G5/F5,"") -> 6565504.7 | I5: 1 | J5: FAIR | K5: Press: $45.9M for seven LEH (Hyde-Smith, Jul 2018)
A6: 70B02C19F00000617 | B6: 0 | C6: 43691 | D6: 2019 | E6: LIGHT ENFORCEMENT HELICOPTERS | F6: 9 | G6: 59150960 | H6: =IF(F6>0,G6/F6,"") -> 6572328.8 | I6: 1 | J6: FAIR | K6: Nine aircraft; option for a tenth (Hyde-Smith $59.1M release)
A7: 70B02C19F00000617 | B7: P00001 | C7: 44068 | D7: 2020 | E7: EXERCISE OPTION TO ORDER LEH 10 | F7: 1 | G7: 6570194.6 | H7: =IF(F7>0,G7/F7,"") -> 6570194.6 | I7: 1 | J7: FAIR | K7: Mod text: exercise option to order LEH 10
A8: 70B02C21F00000080 | B8: 0 | C8: 44231 | D8: 2021 | E8: LIGHT ENFORCEMENT HELICOPTERS | F8: 3 | G8: 21257234 | H8: =IF(F8>0,G8/F8,"") -> 7085744.7 | I8: 1 | J8: FAIR | K8: Initial three of up to nine (Hyde-Smith $21.2M release)
A9: 70B02C21F00000080 | B9: P00001 | C9: 44238 | D9: 2021 | E9: ORDER LEH NUMBER 4 THROUGH 7 | F9: 4 | G9: 27940939 | H9: =IF(F9>0,G9/F9,"") -> 6985234.7 | I9: 1 | J9: FAIR | K9: Mod text: order LEH number 4 through 7
A10: 70B02C18F00000452 | B10: P00003 | C10: 44574 | D10: 2022 | E10: DEOB MOD | F10: 0 | G10: -646.57 | H10: =IF(F10>0,G10/F10,"") | I10: 1 | J10: FAIR | K10: Not an aircraft action (configuration upgrade or simulator)
A11: 70B02C21F00000080 | B11: P00004 | C11: 44816 | D11: 2022 | E11: ORDER TWO LIGHT ENFORCEMENT HELICOPTERS (LEH) | F11: 2 | G11: 14389603 | H11: =IF(F11>0,G11/F11,"") -> 7194801.6 | I11: 1 | J11: FAIR | K11: Mod text: order two LEH
A12: 70B02C23F00000959 | B12: 0 | C12: 45188 | D12: 2023 | E12: LIGHT ENFORCEMENT PLATFORM (LEP) HELICOPTERS | F12: 1 | G12: 9671741.8 | H12: =IF(F12>0,G12/F12,"") -> 9671741.8 | I12: 1 | J12: FAIR | K12: Inferred: one aircraft at base; price likely includes one-time costs
A13: 70B02C23F00000959 | B13: P00002 | C13: 45510 | D13: 2024 | E13: ORDER 3 LIGHT ENFORCEMENT HELICOPTERS (LEPS) | F13: 3 | G13: 24630323 | H13: =IF(F13>0,G13/F13,"") -> 8210107.8 | I13: 1 | J13: FAIR | K13: Mod text: order 3 LEPs
A14: 70B02C23F00000959 | B14: P00003 | C14: 45757 | D14: 2025 | E14: FLIR 380 HD UPGRADE TO A FLIR 380X FOR THE H125 HELICOPTER | F14: 0 | G14: 217964.1 | H14: =IF(F14>0,G14/F14,"") | I14: 1 | J14: FAIR | K14: Not an aircraft action (configuration upgrade or simulator)
A15: 70B02C25F00000274 | B15: 0 | C15: 45757 | D15: 2025 | E15: H125 SIMULATOR/FLIGHT TRAINING DEVICE FOR TRAINING AIR AND MARINE PILOTS | F15: 0 | G15: 1992280 | H15: =IF(F15>0,G15/F15,"") | I15: 1 | J15: CSA | K15: Not an aircraft action (configuration upgrade or simulator)
A16: 70B02C23F00000959 | B16: P00004 | C16: 45909 | D16: 2025 | E16: ORDER 2 LIGHT ENFORCEMENT HELICOPTERS | F16: 2 | G16: 17618473 | H16: =IF(F16>0,G16/F16,"") -> 8809236.3 | I16: 1 | J16: FAIR | K16: Mod text: order 2 LEH
... A19: 70B02C26F00000854 | B19: 0 | C19: 46268 | D19: 2026 | E19: LIGHT ENFORCEMENT PLATFORM SIMULATOR | F19: 0 | G19: 2974000 | H19: =IF(F19>0,G19/F19,"") | I19: 1 | J19: CSA | K19: Not an aircraft action (configuration upgrade or simulator)
A20: Total | F20: =SUM(F5:F19) -> 42 | G20: =SUM(G5:G19) -> 3.2801441e+08
A22: Order summary
A23: Order | B23: First action | C23: Aircraft | D23: Aircraft obligations | E23: Other obligations | F23: Per aircraft | G23: Offers
A24: 70B02C18F00000452 | B24: 43299 | C24: =SUMIFS($F$5:$F$19,$A$5:$A$19,A24) -> 7 | D24: =SUMIFS($G$5:$G$19,$A$5:$A$19,A24,$F$5:$F$19,">0") -> 45958533 | E24: =SUMIFS($G$5:$G$19,$A$5:$A$19,A24,$F$5:$F$19,0) -> -646.57 | F24: =IF(C24>0,D24/C24,"") -> 6565504.7 | G24: 1
A25: 70B02C19F00000617 | B25: 43691 | C25: =SUMIFS($F$5:$F$19,$A$5:$A$19,A25) -> 10 | D25: =SUMIFS($G$5:$G$19,$A$5:$A$19,A25,$F$5:$F$19,">0") -> 65721154 | E25: =SUMIFS($G$5:$G$19,$A$5:$A$19,A25,$F$5:$F$19,0) -> 0 | F25: =IF(C25>0,D25/C25,"") -> 6572115.4 | G25: 1
A26: 70B02C21F00000080 | B26: 44231 | C26: =SUMIFS($F$5:$F$19,$A$5:$A$19,A26) -> 9 | D26: =SUMIFS($G$5:$G$19,$A$5:$A$19,A26,$F$5:$F$19,">0") -> 63587776 | E26: =SUMIFS($G$5:$G$19,$A$5:$A$19,A26,$F$5:$F$19,0) -> 0 | F26: =IF(C26>0,D26/C26,"") -> 7065308.4 | G26: 1
A27: 70B02C23F00000959 | B27: 45188 | C27: =SUMIFS($F$5:$F$19,$A$5:$A$19,A27) -> 6 | D27: =SUMIFS($G$5:$G$19,$A$5:$A$19,A27,$F$5:$F$19,">0") -> 51920538 | E27: =SUMIFS($G$5:$G$19,$A$5:$A$19,A27,$F$5:$F$19,0) -> 352964.1 | F27: =IF(C27>0,D27/C27,"") -> 8653423 | G27: 1
A28: 70B02C25F00000274 | B28: 45757 | C28: =SUMIFS($F$5:$F$19,$A$5:$A$19,A28) -> 0 | D28: =SUMIFS($G$5:$G$19,$A$5:$A$19,A28,$F$5:$F$19,">0") -> 0 | E28: =SUMIFS($G$5:$G$19,$A$5:$A$19,A28,$F$5:$F$19,0) -> 1992280 | F28: =IF(C28>0,D28/C28,"") | G28: 1
A29: 70B02C26F00000290 | B29: 46161 | C29: =SUMIFS($F$5:$F$19,$A$5:$A$19,A29) -> 10 | D29: =SUMIFS($G$5:$G$19,$A$5:$A$19,A29,$F$5:$F$19,">0") -> 95507814 | E29: =SUMIFS($G$5:$G$19,$A$5:$A$19,A29,$F$5:$F$19,0) -> 0 | F29: =IF(C29>0,D29/C29,"") -> 9550781.4 | G29: 2
A30: 70B02C26F00000854 | B30: 46268 | C30: =SUMIFS($F$5:$F$19,$A$5:$A$19,A30) -> 0 | D30: =SUMIFS($G$5:$G$19,$A$5:$A$19,A30,$F$5:$F$19,">0") -> 0 | E30: =SUMIFS($G$5:$G$19,$A$5:$A$19,A30,$F$5:$F$19,0) -> 2974000 | F30: =IF(C30>0,D30/C30,"") | G30: 1
A31: Total | C31: =SUM(C24:C30) -> 42 | D31: =SUM(D24:D30) -> 3.2269581e+08 | E31: =SUM(E24:E30) -> 5318597.5
A33: How much of the price is configuration?
A34: FWS H125, lightly equipped, MAS order 140D0422F0391 (May 2022) | G34: 4770051
A35: CBP H125, configured, P00004 to 70B02C21F00000080 (Sep 2022) | G35: =H11 -> 7194801.6
A36: Configuration and related work as share of configured price | G36: =1-G34/G35 -> 0.33701424
A37: Third-party equipment on CBP orders: FLIR 380X upgrade (P00003, Apr 2025) and Troll switch integration (P00006, Apr 2026). Both fall outside the RFI's Phase 1 scope.
A39: Price per aircraft by ordering action (chart data)
A40: Action | B40: Per aircraft
A41: Jul 2018 | B41: =H5 -> 6565504.7
A42: Aug 2019 | B42: =H6 -> 6572328.8
A43: Aug 2020 | B43: =H7 -> 6570194.6
A44: Feb 2021 | B44: =H8 -> 7085744.7
A45: Feb 2021 | B45: =H9 -> 6985234.7
A46: Sep 2022 | B46: =H11 -> 7194801.6
...

Sheet Contract Sales
A1: Reported schedule sales on GS-07F-139DA (SSQ+), FY2017 Q2 to FY2026 Q2
A2: Sales are reported at invoicing, usually aircraft delivery, so they lag FPDS orders. Nonzero quarters only.
A4: FY | B4: Quarter | C4: Period | D4: SIN | E4: Customer type | F4: Sales | H4: By fiscal year
A5: 2020 | B5: 1 | C5: =A5+B5/10 -> 2020.1 | D5: 567 99 | E5: State or Local Gov | F5: 8160589 | H5: FY | I5: Federal | J5: State or local | K5: Disaster recovery | L5: Total | M5: State/local share
A6: 2020 | B6: 4 | C6: =A6+B6/10 -> 2020.4 | D6: 332216 | E6: Standard | F6: 11464665 | H6: 2017 | I6: =SUMIFS($F$5:$F$40,$A$5:$A$40,H6,$E$5:$E$40,"Standard") -> 0 | J6: =SUMIFS($F$5:$F$40,$A$5:$A$40,H6,$E$5:$E$40,"State or Local Gov") -> 0 | K6: =SUMIFS($F$5:$F$40,$A$5:$A$40,H6,$E$5:$E$40,"Recovery") -> 0 | L6: =SUM(I6:K6) -> 0 | M6: =IF(L6>0,J6/L6,"")
A7: 2020 | B7: 4 | C7: =A7+B7/10 -> 2020.4 | D7: 336413 | E7: Standard | F7: 14591991 | H7: 2018 | I7: =SUMIFS($F$5:$F$40,$A$5:$A$40,H7,$E$5:$E$40,"Standard") -> 0 | J7: =SUMIFS($F$5:$F$40,$A$5:$A$40,H7,$E$5:$E$40,"State or Local Gov") -> 0 | K7: =SUMIFS($F$5:$F$40,$A$5:$A$40,H7,$E$5:$E$40,"Recovery") -> 0 | L7: =SUM(I7:K7) -> 0 | M7: =IF(L7>0,J7/L7,"")
A8: 2021 | B8: 1 | C8: =A8+B8/10 -> 2021.1 | D8: 332216 | E8: Standard | F8: 33697466 | H8: 2019 | I8: =SUMIFS($F$5:$F$40,$A$5:$A$40,H8,$E$5:$E$40,"Standard") -> 0 | J8: =SUMIFS($F$5:$F$40,$A$5:$A$40,H8,$E$5:$E$40,"State or Local Gov") -> 0 | K8: =SUMIFS($F$5:$F$40,$A$5:$A$40,H8,$E$5:$E$40,"Recovery") -> 0 | L8: =SUM(I8:K8) -> 0 | M8: =IF(L8>0,J8/L8,"")
A9: 2021 | B9: 1 | C9: =A9+B9/10 -> 2021.1 | D9: 336413 | E9: State or Local Gov | F9: 9876395 | H9: 2020 | I9: =SUMIFS($F$5:$F$40,$A$5:$A$40,H9,$E$5:$E$40,"Standard") -> 26056656 | J9: =SUMIFS($F$5:$F$40,$A$5:$A$40,H9,$E$5:$E$40,"State or Local Gov") -> 8160589 | K9: =SUMIFS($F$5:$F$40,$A$5:$A$40,H9,$E$5:$E$40,"Recovery") -> 0 | L9: =SUM(I9:K9) -> 34217245 | M9: =IF(L9>0,J9/L9,"") -> 0.23849346
A10: 2021 | B10: 1 | C10: =A10+B10/10 -> 2021.1 | D10: OLM | E10: State or Local Gov | F10: 17874 | H10: 2021 | I10: =SUMIFS($F$5:$F$40,$A$5:$A$40,H10,$E$5:$E$40,"Standard") -> 66255243 | J10: =SUMIFS($F$5:$F$40,$A$5:$A$40,H10,$E$5:$E$40,"State or Local Gov") -> 10417913 | K10: =SUMIFS($F$5:$F$40,$A$5:$A$40,H10,$E$5:$E$40,"Recovery") -> 0 | L10: =SUM(I10:K10) -> 76673156 | M10: =IF(L10>0,J10/L10,"") -> 0.13587432
A11: 2021 | B11: 2 | C11: =A11+B11/10 -> 2021.2 | D11: 332216 | E11: Standard | F11: 11687418 | H11: 2022 | I11: =SUMIFS($F$5:$F$40,$A$5:$A$40,H11,$E$5:$E$40,"Standard") -> 16304729 | J11: =SUMIFS($F$5:$F$40,$A$5:$A$40,H11,$E$5:$E$40,"State or Local Gov") -> 0 | K11: =SUMIFS($F$5:$F$40,$A$5:$A$40,H11,$E$5:$E$40,"Recovery") -> 6348372 | L11: =SUM(I11:K11) -> 22653101 | M11: =IF(L11>0,J11/L11,"") -> 0
A12: 2021 | B12: 2 | C12: =A12+B12/10 -> 2021.2 | D12: 336413 | E12: Standard | F12: 3887278 | H12: 2023 | I12: =SUMIFS($F$5:$F$40,$A$5:$A$40,H12,$E$5:$E$40,"Standard") -> 53148289 | J12: =SUMIFS($F$5:$F$40,$A$5:$A$40,H12,$E$5:$E$40,"State or Local Gov") -> 22683187 | K12: =SUMIFS($F$5:$F$40,$A$5:$A$40,H12,$E$5:$E$40,"Recovery") -> 0 | L12: =SUM(I12:K12) -> 75831476 | M12: =IF(L12>0,J12/L12,"") -> 0.29912628
A13: 2021 | B13: 3 | C13: =A13+B13/10 -> 2021.3 | D13: 332216 | E13: Standard | F13: 5661027 | H13: 2024 | I13: =SUMIFS($F$5:$F$40,$A$5:$A$40,H13,$E$5:$E$40,"Standard") -> 12296946 | J13: =SUMIFS($F$5:$F$40,$A$5:$A$40,H13,$E$5:$E$40,"State or Local Gov") -> 22154653 | K13: =SUMIFS($F$5:$F$40,$A$5:$A$40,H13,$E$5:$E$40,"Recovery") -> 0 | L13: =SUM(I13:K13) -> 34451599 | M13: =IF(L13>0,J13/L13,"") -> 0.64306603
A14: 2021 | B14: 4 | C14: =A14+B14/10 -> 2021.4 | D14: 332216 | E14: Standard | F14: 11322054 | H14: 2025 | I14: =SUMIFS($F$5:$F$40,$A$5:$A$40,H14,$E$5:$E$40,"Standard") -> 884201 | J14: =SUMIFS($F$5:$F$40,$A$5:$A$40,H14,$E$5:$E$40,"State or Local Gov") -> 10450824 | K14: =SUMIFS($F$5:$F$40,$A$5:$A$40,H14,$E$5:$E$40,"Recovery") -> 0 | L14: =SUM(I14:K14) -> 11335025 | M14: =IF(L14>0,J14/L14,"") -> 0.92199391
A15: 2021 | B15: 4 | C15: =A15+B15/10 -> 2021.4 | D15: 336413 | E15: State or Local Gov | F15: 523644 | H15: 2026 | I15: =SUMIFS($F$5:$F$40,$A$5:$A$40,H15,$E$5:$E$40,"Standard") -> 0 | J15: =SUMIFS($F$5:$F$40,$A$5:$A$40,H15,$E$5:$E$40,"State or Local Gov") -> 38769551 | K15: =SUMIFS($F$5:$F$40,$A$5:$A$40,H15,$E$5:$E$40,"Recovery") -> 0 | L15: =SUM(I15:K15) -> 38769551 | M15: =IF(L15>0,J15/L15,"") -> 1
A16: 2022 | B16: 1 | C16: =A16+B16/10 -> 2022.1 | D16: 332216 | E16: Standard | F16: 10634709 | H16: Total | I16: =SUM(I6:I15) -> 174946064 | J16: =SUM(J6:J15) -> 112636717 | K16: =SUM(K6:K15) -> 6348372 | L16: =SUM(L6:L15) -> 293931153 | M16: =J16/L16 -> 0.38320782
A17: 2022 | B17: 1 | C17: =A17+B17/10 -> 2022.1 | D17: 336413 | E17: Recovery | F17: 6348372
A18: 2022 | B18: 3 | C18: =A18+B18/10 -> 2022.3 | D18: 334516 | E18: Standard | F18: 2248 | H18: By SIN (helicopter sales were reported under three SINs)
A19: 2022 | B19: 4 | C19: =A19+B19/10 -> 2022.4 | D19: 334516 | E19: Standard | F19: 6745 | H19: SIN | I19: Federal | J19: State or local | K19: Disaster recovery | L19: Total | M19: SIN title
A20: 2022 | B20: 4 | C20: =A20+B20/10 -> 2022.4 | D20: 336413 | E20: Standard | F20: 5661027 | H20: 567 99 | I20: =SUMIFS($F$5:$F$40,$D$5:$D$40,H20,$E$5:$E$40,"Standard") -> 0 | J20: =SUMIFS($F$5:$F$40,$D$5:$D$40,H20,$E$5:$E$40,"State or Local Gov") -> 8160589 | K20: =SUMIFS($F$5:$F$40,$D$5:$D$40,H20,$E$5:$E$40,"Recovery") -> 0 | L20: =SUM(I20:K20) -> 8160589 | M20: Legacy Schedule 84 new products SIN
A21: 2023 | B21: 1 | C21: =A21+B21/10 -> 2023.1 | D21: 334516 | E21: Standard | F21: 14963 | H21: 332216 | I21: =SUMIFS($F$5:$F$40,$D$5:$D$40,H21,$E$5:$E$40,"Standard") -> 84467339 | J21: =SUMIFS($F$5:$F$40,$D$5:$D$40,H21,$E$5:$E$40,"State or Local Gov") -> 0 | K21: =SUMIFS($F$5:$F$40,$D$5:$D$40,H21,$E$5:$E$40,"Recovery") -> 0 | L21: =SUM(I21:K21) -> 84467339 | M21: Law Enforcement, Firefighting and Rescue Tools, Equipment and Accessories (Cooperative Purchasing)
A22: 2023 | B22: 1 | C22: =A22+B22/10 -> 2023.1 | D22: 336413 | E22: Standard | F22: 41941204 | H22: 336413 | I22: =SUMIFS($F$5:$F$40,$D$5:$D$40,H22,$E$5:$E$40,"Standard") -> 90450519 | J22: =SUMIFS($F$5:$F$40,$D$5:$D$40,H22,$E$5:$E$40,"State or Local Gov") -> 104458254 | K22: =SUMIFS($F$5:$F$40,$D$5:$D$40,H22,$E$5:$E$40,"Recovery") -> 6348372 | L22: =SUM(I22:K22) -> 201257145 | M22: Aircraft Armoring and Helicopter Equipment (complete aircraft excluded by Refresh 26, Apr 2025)
A23: 2023 | B23: 2 | C23: =A23+B23/10 -> 2023.2 | D23: 336413 | E23: Standard | F23: 5932139 | H23: OLM | I23: =SUMIFS($F$5:$F$40,$D$5:$D$40,H23,$E$5:$E$40,"Standard") -> 0 | J23: =SUMIFS($F$5:$F$40,$D$5:$D$40,H23,$E$5:$E$40,"State or Local Gov") -> 17874 | K23: =SUMIFS($F$5:$F$40,$D$5:$D$40,H23,$E$5:$E$40,"Recovery") -> 0 | L23: =SUM(I23:K23) -> 17874 | M23: Order-level materials
A24: 2023 | B24: 2 | C24: =A24+B24/10 -> 2023.2 | D24: 336413 | E24: State or Local Gov | F24: 11696945 | H24: 334516 | I24: =SUMIFS($F$5:$F$40,$D$5:$D$40,H24,$E$5:$E$40,"Standard") -> 28206 | J24: =SUMIFS($F$5:$F$40,$D$5:$D$40,H24,$E$5:$E$40,"State or Local Gov") -> 0 | K24: =SUMIFS($F$5:$F$40,$D$5:$D$40,H24,$E$5:$E$40,"Recovery") -> 0 | L24: =SUM(I24:K24) -> 28206 | M24: Other (COVID test kits)
A25: 2023 | B25: 4 | C25: =A25+B25/10 -> 2023.4 | D25: 334516 | E25: Standard | F25: 2000
A26: 2023 | B26: 4 | C26: =A26+B26/10 -> 2023.4 | D26: 336413 | E26: Standard | F26: 5257983 | H26: Derived figures
A27: 2023 | B27: 4 | C27: =A27+B27/10 -> 2023.4 | D27: 336413 | E27: State or Local Gov | F27: 10986242 | H27: Sales on SIN 336413 after the Refresh 26 exclusion (FY2025 Q3 on) | I27: =SUMIFS($F$5:$F$40,$D$5:$D$40,"336413",$C$5:$C$40,">=2025.3") -> 39276140
A28: 2024 | B28: 1 | C28: =A28+B28/10 -> 2024.1 | D28: 334516 | E28: Standard | F28: 2250 | H28: State/local sales reported FY2025-FY2026 (possibly CBP deliveries) | I28: =SUMIFS($F$5:$F$40,$E$5:$E$40,"State or Local Gov",$A$5:$A$40,">=2025") -> 49220375
A29: 2024 | B29: 1 | C29: =A29+B29/10 -> 2024.1 | D29: 336413 | E29: Standard | F29: 12209696 | H29: State/local sales, as reported | I29: =J16 -> 112636717
A30: 2024 | B30: 1 | C30: =A30+B30/10 -> 2024.1 | D30: 336413 | E30: State or Local Gov | F30: 6167178 | H30: State/local sales, low reading (FY2025-26 reassigned to federal) | I30: =J16-I28 -> 63416342
A31: 2024 | B31: 2 | C31: =A31+B31/10 -> 2024.2 | D31: 336413 | E31: State or Local Gov | F31: 10309749 | H31: State/local share of total sales, as reported | I31: =J16/L16 -> 0.38320782
A32: 2024 | B32: 3 | C32: =A32+B32/10 -> 2024.3 | D32: 336413 | E32: State or Local Gov | F32: 5677726 | H32: State/local share of total sales, low reading | I32: =I30/L16 -> 0.21575237
A33: 2024 | B33: 4 | C33: =A33+B33/10 -> 2024.4 | D33: 336413 | E33: Standard | F33: 85000 | H33: Years of reported sales (FY2020 Q1 to FY2026 Q2) | I33: 6.5
A34: 2025 | B34: 1 | C34: =A34+B34/10 -> 2025.1 | D34: 336413 | E34: Standard | F34: 255629 | H34: Average annual sales | I34: =L16/I33 -> 45220177
A35: 2025 | B35: 1 | C35: =A35+B35/10 -> 2025.1 | D35: 336413 | E35: State or Local Gov | F35: 3875000 | H35: State/local sales per year (low reading) | I35: =I30/I33 -> 9756360.3
A36: 2025 | B36: 2 | C36: =A36+B36/10 -> 2025.2 | D36: 336413 | E36: Standard | F36: 121983 | H36: State/local sales per year (as reported) | I36: =J16/I33 -> 17328726
A37: 2025 | B37: 2 | C37: =A37+B37/10 -> 2025.2 | D37: 336413 | E37: State or Local Gov | F37: 6575824 | H37: Federal sales fall to $0.9M over FY2025-FY2026 while CBP had $42M in aircraft due for delivery; the low reading treats that window's state/local sales as CBP. Contractor confirmation not available.
A38: 2025 | B38: 4 | C38: =A38+B38/10 -> 2025.4 | D38: 336413 | E38: Standard | F38: 506589
A39: 2026 | B39: 1 | C39: =A39+B39/10 -> 2026.1 | D39: 336413 | E39: State or Local Gov | F39: 3883902
A40: 2026 | B40: 2 | C40: =A40+B40/10 -> 2026.2 | D40: 336413 | E40: State or Local Gov | F40: 34885649

Sheet Buyers & Competition
A1: Who buys, through what, and how much competition
A2: All figures are formulas over the Purchases tab unless noted.
A4: By buyer
A5: Customer | B5: Purchases | C5: Share | D5: Aircraft (known) | E5: Awards | F5: Avg offers (where reported) | G5: Main vendor
A6: CBP | B6: =SUMIFS(Purchases!$H$5:$H$24,Purchases!$B$5:$B$24,A6) -> 323050000 | C6: =B6/Purchases!$H$25 -> 0.63398953 | D6: =SUMIFS(Purchases!$G$5:$G$24,Purchases!$B$5:$B$24,A6) -> 42 | E6: =COUNTIFS(Purchases!$B$5:$B$24,A6) -> 5 | F6: =IFERROR(AVERAGEIFS(Purchases!$J$5:$J$24,Purchases!$B$5:$B$24,A6),"n/r") -> 1.2 | G6: Davenport Aviation
A7: DOI US Park Police | B7: =SUMIFS(Purchases!$H$5:$H$24,Purchases!$B$5:$B$24,A7) -> 53240000 | C7: =B7/Purchases!$H$25 -> 0.10448414 | D7: =SUMIFS(Purchases!$G$5:$G$24,Purchases!$B$5:$B$24,A7) -> 0 | E7: =COUNTIFS(Purchases!$B$5:$B$24,A7) -> 1 | F7: =IFERROR(AVERAGEIFS(Purchases!$J$5:$J$24,Purchases!$B$5:$B$24,A7),"n/r") -> 1 | G7: Bell Textron
A8: DOE NNSA | B8: =SUMIFS(Purchases!$H$5:$H$24,Purchases!$B$5:$B$24,A8) -> 36006000 | C8: =B8/Purchases!$H$25 -> 0.07066221 | D8: =SUMIFS(Purchases!$G$5:$G$24,Purchases!$B$5:$B$24,A8) -> 2 | E8: =COUNTIFS(Purchases!$B$5:$B$24,A8) -> 1 | F8: =IFERROR(AVERAGEIFS(Purchases!$J$5:$J$24,Purchases!$B$5:$B$24,A8),"n/r") -> 4 | G8: Leonardo Helicopters
A9: FBI | B9: =SUMIFS(Purchases!$H$5:$H$24,Purchases!$B$5:$B$24,A9) -> 35932000 | C9: =B9/Purchases!$H$25 -> 0.070516985 | D9: =SUMIFS(Purchases!$G$5:$G$24,Purchases!$B$5:$B$24,A9) -> 5 | E9: =COUNTIFS(Purchases!$B$5:$B$24,A9) -> 2 | F9: =IFERROR(AVERAGEIFS(Purchases!$J$5:$J$24,Purchases!$B$5:$B$24,A9),"n/r") -> n/r | G9: Bell Textron
A10: DEA | B10: =SUMIFS(Purchases!$H$5:$H$24,Purchases!$B$5:$B$24,A10) -> 19287000 | C10: =B10/Purchases!$H$25 -> 0.037850971 | D10: =SUMIFS(Purchases!$G$5:$G$24,Purchases!$B$5:$B$24,A10) -> 2 | E10: =COUNTIFS(Purchases!$B$5:$B$24,A10) -> 3 | F10: =IFERROR(AVERAGEIFS(Purchases!$J$5:$J$24,Purchases!$B$5:$B$24,A10),"n/r") -> 1 | G10: Bell Textron
A11: NASA | B11: =SUMIFS(Purchases!$H$5:$H$24,Purchases!$B$5:$B$24,A11) -> 18480000 | C11: =B11/Purchases!$H$25 -> 0.036267223 | D11: =SUMIFS(Purchases!$G$5:$G$24,Purchases!$B$5:$B$24,A11) -> 3 | E11: =COUNTIFS(Purchases!$B$5:$B$24,A11) -> 1 | F11: =IFERROR(AVERAGEIFS(Purchases!$J$5:$J$24,Purchases!$B$5:$B$24,A11),"n/r") -> 1 | G11: Davenport Aviation
A12: USDA APHIS | B12: =SUMIFS(Purchases!$H$5:$H$24,Purchases!$B$5:$B$24,A12) -> 7450000 | C12: =B12/Purchases!$H$25 -> 0.014620715 | D12: =SUMIFS(Purchases!$G$5:$G$24,Purchases!$B$5:$B$24,A12) -> 1 | E12: =COUNTIFS(Purchases!$B$5:$B$24,A12) -> 2 | F12: =IFERROR(AVERAGEIFS(Purchases!$J$5:$J$24,Purchases!$B$5:$B$24,A12),"n/r") -> 2.5 | G12: Shier Aviation
A13: DOE WAPA | B13: =SUMIFS(Purchases!$H$5:$H$24,Purchases!$B$5:$B$24,A13) -> 5872000 | C13: =B13/Purchases!$H$25 -> 0.011523871 | D13: =SUMIFS(Purchases!$G$5:$G$24,Purchases!$B$5:$B$24,A13) -> 2 | E13: =COUNTIFS(Purchases!$B$5:$B$24,A13) -> 2 | F13: =IFERROR(AVERAGEIFS(Purchases!$J$5:$J$24,Purchases!$B$5:$B$24,A13),"n/r") -> 2.5 | G13: Bell Textron
A14: DOI FWS | B14: =SUMIFS(Purchases!$H$5:$H$24,Purchases!$B$5:$B$24,A14) -> 4770000 | C14: =B14/Purchases!$H$25 -> 0.0093611827 | D14: =SUMIFS(Purchases!$G$5:$G$24,Purchases!$B$5:$B$24,A14) -> 1 | E14: =COUNTIFS(Purchases!$B$5:$B$24,A14) -> 1 | F14: =IFERROR(AVERAGEIFS(Purchases!$J$5:$J$24,Purchases!$B$5:$B$24,A14),"n/r") -> 1 | G14: Davenport Aviation
A15: NPS | B15: =SUMIFS(Purchases!$H$5:$H$24,Purchases!$B$5:$B$24,A15) -> 4633000 | C15: =B15/Purchases!$H$25 -> 0.0090923185 | D15: =SUMIFS(Purchases!$G$5:$G$24,Purchases!$B$5:$B$24,A15) -> 1 | E15: =COUNTIFS(Purchases!$B$5:$B$24,A15) -> 1 | F15: =IFERROR(AVERAGEIFS(Purchases!$J$5:$J$24,Purchases!$B$5:$B$24,A15),"n/r") -> 4 | G15: Rainier Heli International
A16: State INL | B16: =SUMIFS(Purchases!$H$5:$H$24,Purchases!$B$5:$B$24,A16) -> 831000 | C16: =B16/Purchases!$H$25 -> 0.0016308476 | D16: =SUMIFS(Purchases!$G$5:$G$24,Purchases!$B$5:$B$24,A16) -> 1 | E16: =COUNTIFS(Purchases!$B$5:$B$24,A16) -> 1 | F16: =IFERROR(AVERAGEIFS(Purchases!$J$5:$J$24,Purchases!$B$5:$B$24,A16),"n/r") -> 9 | G16: unknown
A18: By vehicle
A19: Vehicle | B19: Purchases | C19: Share | D19: Awards | E19: Avg offers | F19: Single-offer awards | G19: Awards reporting offers
A20: GSA MAS | B20: =SUMIFS(Purchases!$H$5:$H$24,Purchases!$C$5:$C$24,A20) -> 346300000 | C20: =B20/Purchases!$H$25 -> 0.67961794 | D20: =COUNTIFS(Purchases!$C$5:$C$24,A20) -> 7 | E20: =IFERROR(AVERAGEIFS(Purchases!$J$5:$J$24,Purchases!$C$5:$C$24,A20),"n/r") -> 1.1428571 | F20: =COUNTIFS(Purchases!$C$5:$C$24,A20,Purchases!$J$5:$J$24,1) -> 6 | G20: =COUNTIFS(Purchases!$C$5:$C$24,A20,Purchases!$J$5:$J$24,">0") -> 7
A21: Agency IDV | B21: =SUMIFS(Purchases!$H$5:$H$24,Purchases!$C$5:$C$24,A21) -> 48399000 | C21: =B21/Purchases!$H$25 -> 0.094983623 | D21: =COUNTIFS(Purchases!$C$5:$C$24,A21) -> 4 | E21: =IFERROR(AVERAGEIFS(Purchases!$J$5:$J$24,Purchases!$C$5:$C$24,A21),"n/r") -> n/r | F21: =COUNTIFS(Purchases!$C$5:$C$24,A21,Purchases!$J$5:$J$24,1) -> 0 | G21: =COUNTIFS(Purchases!$C$5:$C$24,A21,Purchases!$J$5:$J$24,">0") -> 0
A22: Open market | B22: =SUMIFS(Purchases!$H$5:$H$24,Purchases!$C$5:$C$24,A22) -> 114852000 | C22: =B22/Purchases!$H$25 -> 0.22539844 | D22: =COUNTIFS(Purchases!$C$5:$C$24,A22) -> 9 | E22: =IFERROR(AVERAGEIFS(Purchases!$J$5:$J$24,Purchases!$C$5:$C$24,A22),"n/r") -> 3.2222222 | F22: =COUNTIFS(Purchases!$C$5:$C$24,A22,Purchases!$J$5:$J$24,1) -> 3 | G22: =COUNTIFS(Purchases!$C$5:$C$24,A22,Purchases!$J$5:$J$24,">0") -> 9
A23: Agency IDV orders (FBI, DEA with Bell) do not report offers at the order level. FBI's five Bell 429s are two ledger rows (FY2018, FY2021).
A25: By seller
A26: Vendor | B26: Purchases | C26: Share | D26: Non-CBP purchases | E26: Share of non-CBP | F26: Seller type
A27: Davenport Aviation | B27: =SUMIFS(Purchases!$H$5:$H$24,Purchases!$D$5:$D$24,A27) -> 346300000 | C27: =B27/Purchases!$H$25 -> 0.67961794 | D27: =SUMIFS(Purchases!$H$5:$H$24,Purchases!$D$5:$D$24,A27,Purchases!$B$5:$B$24,"<>CBP") -> 23250000 | E27: =D27/SUMIFS(Purchases!$H$5:$H$24,Purchases!$B$5:$B$24,"<>CBP") -> 0.12466421 | F27: Authorized dealer on MAS (Airbus)
A28: Bell Textron | B28: =SUMIFS(Purchases!$H$5:$H$24,Purchases!$D$5:$D$24,A28) -> 114331000 | C28: =B28/Purchases!$H$25 -> 0.22437597 | D28: =SUMIFS(Purchases!$H$5:$H$24,Purchases!$D$5:$D$24,A28,Purchases!$B$5:$B$24,"<>CBP") -> 114331000 | E28: =D28/SUMIFS(Purchases!$H$5:$H$24,Purchases!$B$5:$B$24,"<>CBP") -> 0.61303157 | F28: OEM direct
A29: Leonardo Helicopters | B29: =SUMIFS(Purchases!$H$5:$H$24,Purchases!$D$5:$D$24,A29) -> 36006000 | C29: =B29/Purchases!$H$25 -> 0.07066221 | D29: =SUMIFS(Purchases!$H$5:$H$24,Purchases!$D$5:$D$24,A29,Purchases!$B$5:$B$24,"<>CBP") -> 36006000 | E29: =D29/SUMIFS(Purchases!$H$5:$H$24,Purchases!$B$5:$B$24,"<>CBP") -> 0.19306063 | F29: OEM direct
A30: Rainier Heli International | B30: =SUMIFS(Purchases!$H$5:$H$24,Purchases!$D$5:$D$24,A30) -> 4633000 | C30: =B30/Purchases!$H$25 -> 0.0090923185 | D30: =SUMIFS(Purchases!$H$5:$H$24,Purchases!$D$5:$D$24,A30,Purchases!$B$5:$B$24,"<>CBP") -> 4633000 | E30: =D30/SUMIFS(Purchases!$H$5:$H$24,Purchases!$B$5:$B$24,"<>CBP") -> 0.02484169 | F30: Dealer or used-aircraft seller
A31: Shier Aviation | B31: =SUMIFS(Purchases!$H$5:$H$24,Purchases!$D$5:$D$24,A31) -> 4600000 | C31: =B31/Purchases!$H$25 -> 0.0090275556 | D31: =SUMIFS(Purchases!$H$5:$H$24,Purchases!$D$5:$D$24,A31,Purchases!$B$5:$B$24,"<>CBP") -> 4600000 | E31: =D31/SUMIFS(Purchases!$H$5:$H$24,Purchases!$B$5:$B$24,"<>CBP") -> 0.024664747 | F31: Dealer or used-aircraft seller
A32: Trinity Aviation | B32: =SUMIFS(Purchases!$H$5:$H$24,Purchases!$D$5:$D$24,A32) -> 2850000 | C32: =B32/Purchases!$H$25 -> 0.0055931595 | D32: =SUMIFS(Purchases!$H$5:$H$24,Purchases!$D$5:$D$24,A32,Purchases!$B$5:$B$24,"<>CBP") -> 2850000 | E32: =D32/SUMIFS(Purchases!$H$5:$H$24,Purchases!$B$5:$B$24,"<>CBP") -> 0.015281419 | F32: Dealer or used-aircraft seller
A33: unknown | B33: =SUMIFS(Purchases!$H$5:$H$24,Purchases!$D$5:$D$24,A33) -> 831000 | C33: =B33/Purchases!$H$25 -> 0.0016308476 | D33: =SUMIFS(Purchases!$H$5:$H$24,Purchases!$D$5:$D$24,A33,Purchases!$B$5:$B$24,"<>CBP") -> 831000 | E33: =D33/SUMIFS(Purchases!$H$5:$H$24,Purchases!$B$5:$B$24,"<>CBP") -> 0.0044557402 | F33: Dealer or used-aircraft seller
A36: Context: all civilian PSC 1520 / helicopter-described obligations, FY2016-FY2026 (includes sustainment)
A37: Buyer (funding sub-agency) | B37: Obligations
A38: U.S. Coast Guard | B38: 6.376675e+08
A39: U.S. Customs and Border Protection | B39: 3.3231236e+08
A40: Department of State | B40: 1.7320015e+08
A41: Departmental Offices | B41: 57982847
A42: Department of Energy | B42: 41878061
A43: Federal Bureau of Investigation | B43: 36260185
A44: Drug Enforcement Administration | B44: 23266220
A45: National Aeronautics and Space Administration | B45: 18867735
...

Sheet Adjacent Spend
A1: Rotary-wing spend outside aircraft purchases, FY2016-FY2026
A2: Floor values: each pull required a helicopter keyword. Fire aviation is barely captured.
A4: Segment | B4: Category | C4: FY | D4: Obligations | F4: Category | G4: Civilian | H4: DoD
A5: Civilian | B5: Aviation services (V1xx) | C5: 2016 | D5: 567243.87 | F5: Parts and components (1615-2995) | G5: =SUMIFS($D$5:$D$86,$A$5:$A$86,"Civilian",$B$5:$B$86,F5) -> 5.6875652e+08 | H5: =SUMIFS($D$5:$D$86,$A$5:$A$86,"DoD",$B$5:$B$86,F5) -> 8.1024395e+09
A6: Civilian | B6: Aviation services (V1xx) | C6: 2017 | D6: 3194237.3 | F6: Maintenance and repair (J01x) | G6: =SUMIFS($D$5:$D$86,$A$5:$A$86,"Civilian",$B$5:$B$86,F6) -> 3.6520116e+08 | H6: =SUMIFS($D$5:$D$86,$A$5:$A$86,"DoD",$B$5:$B$86,F6) -> 3.7133228e+09
A7: Civilian | B7: Aviation services (V1xx) | C7: 2018 | D7: 1795894.9 | F7: Aviation services (V1xx) | G7: =SUMIFS($D$5:$D$86,$A$5:$A$86,"Civilian",$B$5:$B$86,F7) -> 1.5852722e+08 | H7: =SUMIFS($D$5:$D$86,$A$5:$A$86,"DoD",$B$5:$B$86,F7) -> 6.2373594e+08
A8: Civilian | B8: Aviation services (V1xx) | C8: 2019 | D8: 4733344.1 | F8: Modification (K01x) | G8: =SUMIFS($D$5:$D$86,$A$5:$A$86,"Civilian",$B$5:$B$86,F8) -> 366276.83 | H8: =SUMIFS($D$5:$D$86,$A$5:$A$86,"DoD",$B$5:$B$86,F8) -> 14287207
A9: Civilian | B9: Aviation services (V1xx) | C9: 2020 | D9: 5522876 | F9: Adjacent total | G9: =SUM(G5:G8) -> 1.0928512e+09 | H9: =SUM(H5:H8) -> 1.2453785e+10
A10: Civilian | B10: Aviation services (V1xx) | C10: 2021 | D10: 129876686 | F10: Civilian aircraft purchases (Purchases tab) | G10: =Purchases!H25 -> 509551000
A11: Civilian | B11: Aviation services (V1xx) | C11: 2022 | D11: 3908184.6 | F11: Purchases as share of civilian rotary-wing contract spend | G11: =G10/(G9+G10) -> 0.31799195
A12: Civilian | B12: Aviation services (V1xx) | C12: 2023 | D12: 5050556.3
A13: Civilian | B13: Aviation services (V1xx) | C13: 2024 | D13: 1734767.1 | F13: Coast Guard bought 97% of civilian helicopter parts (MH-60T and MH-65 fleets).
A14: Civilian | B14: Aviation services (V1xx) | C14: 2025 | D14: 869175.45 | F14: Segment = funding agency. Parts split uses agency name containing 'Defense'.
A15: Civilian | B15: Aviation services (V1xx) | C15: 2026 | D15: 1274258.1
A16: Civilian | B16: Maintenance and repair (J01x) | C16: 2016 | D16: 11919496
A17: Civilian | B17: Maintenance and repair (J01x) | C17: 2017 | D17: 41371851
A18: Civilian | B18: Maintenance and repair (J01x) | C18: 2018 | D18: 38265401
A19: Civilian | B19: Maintenance and repair (J01x) | C19: 2019 | D19: 38623015
A20: Civilian | B20: Maintenance and repair (J01x) | C20: 2020 | D20: 41552028
A21: Civilian | B21: Maintenance and repair (J01x) | C21: 2021 | D21: 30481911
A22: Civilian | B22: Maintenance and repair (J01x) | C22: 2022 | D22: 37096667
A23: Civilian | B23: Maintenance and repair (J01x) | C23: 2023 | D23: 25192862
A24: Civilian | B24: Maintenance and repair (J01x) | C24: 2024 | D24: 32456382
A25: Civilian | B25: Maintenance and repair (J01x) | C25: 2025 | D25: 32208044
A26: Civilian | B26: Maintenance and repair (J01x) | C26: 2026 | D26: 36033506
... A86: DoD | B86: Parts and components (1615-2995) | C86: 2026 | D86: 1.7201958e+08

Sheet Projection
A1: Five-year volume and IFF projection
A2: Yellow cells are assumptions; change them and the table recalculates. Built on actual contract sales.
A3: Assumption | C3: Value | D3: Basis
A4: Federal sales per year, as reported | C4: ='Contract Sales'!I16/'Contract Sales'!I33 -> 26914779 | D4: SSQ+ federal sales / 6.5 years
A5: Federal sales per year, with FY2025-26 state/local reassigned | C5: =('Contract Sales'!I16+'Contract Sales'!I28)/'Contract Sales'!I33 -> 34487144 | D5: Low reading of state/local
A6: Base federal volume (year 1) | C6: =AVERAGE(C4:C5) -> 30700962 | D6: Midpoint of the two readings
A7: Base state/local volume (year 1) | C7: =AVERAGE('Contract Sales'!I35,'Contract Sales'!I36) -> 13542543 | D7: Midpoint of low and as-reported state/local per year
A8: Annual price growth | C8: 0.05 | D8: CBP per-aircraft price rose ~5%/yr, FY2019-FY2026 (CBP Orders tab)
A9: IFF rate | C9: 0.0075 | D9: MAS Industrial Funding Fee
A10: Bell civilian purchase volume per year | C10: =SUMIFS(Purchases!$H$5:$H$24,Purchases!$D$5:$D$24,"Bell Textron")/11 -> 10393727 | D10: Purchases tab, Bell Textron, FY2016-FY2026 / 11 years
A11: Share of Bell volume moving to MAS if a Bell dealer is awarded | C11: 0.33333333 | D11: Assumption: one-third, starting year 3
A12: Year a Bell dealer is awarded | C12: 3 | D12: Assumption
A14: Projection built on actuals
A15: Year | C15: Federal | D15: State/local | E15: Bell upside | F15: Total | G15: IFF | H15: Change package total | I15: Change package IFF
A16: 1 | C16: =$C$6*(1+$C$8)^(A16-1) -> 30700962 | D16: =$C$7*(1+$C$8)^(A16-1) -> 13542543 | E16: =IF(A16>=$C$12,$C$10*$C$11*(1+$C$8)^(A16-1),0) -> 0 | F16: =SUM(C16:E16) -> 44243505 | G16: =F16*$C$9 -> 331826.29 | H16: 50000000 | I16: 375000
A17: 2 | C17: =$C$6*(1+$C$8)^(A17-1) -> 32236010 | D17: =$C$7*(1+$C$8)^(A17-1) -> 14219670 | E17: =IF(A17>=$C$12,$C$10*$C$11*(1+$C$8)^(A17-1),0) -> 0 | F17: =SUM(C17:E17) -> 46455680 | G17: =F17*$C$9 -> 348417.6 | H17: 66500000 | I17: 498750
A18: 3 | C18: =$C$6*(1+$C$8)^(A18-1) -> 33847810 | D18: =$C$7*(1+$C$8)^(A18-1) -> 14930654 | E18: =IF(A18>=$C$12,$C$10*$C$11*(1+$C$8)^(A18-1),0) -> 3819694.8 | F18: =SUM(C18:E18) -> 52598159 | G18: =F18*$C$9 -> 394486.19 | H18: 78349500 | I18: 587621
A19: 4 | C19: =$C$6*(1+$C$8)^(A19-1) -> 35540201 | D19: =$C$7*(1+$C$8)^(A19-1) -> 15677186 | E19: =IF(A19>=$C$12,$C$10*$C$11*(1+$C$8)^(A19-1),0) -> 4010679.5 | F19: =SUM(C19:E19) -> 55228067 | G19: =F19*$C$9 -> 414210.5 | H19: 90563620 | I19: 679227
A20: 5 | C20: =$C$6*(1+$C$8)^(A20-1) -> 37317211 | D20: =$C$7*(1+$C$8)^(A20-1) -> 16461046 | E20: =IF(A20>=$C$12,$C$10*$C$11*(1+$C$8)^(A20-1),0) -> 4211213.5 | F20: =SUM(C20:E20) -> 57989470 | G20: =F20*$C$9 -> 434921.03 | H20: 103158073 | I20: 773686
A21: 5-year total | C21: =SUM(C16:C20) -> 1.6964219e+08 | D21: =SUM(D16:D20) -> 74831099 | E21: =SUM(E16:E20) -> 12041588 | F21: =SUM(F16:F20) -> 2.5651488e+08 | G21: =SUM(G16:G20) -> 1923861.6 | H21: =SUM(H16:H20) -> 388571193 | I21: =SUM(I16:I20) -> 2914284
A22: Projection as share of change package | F22: =F21/H21 -> 0.66014899
A24: Change package columns: completed draft MCP 2026-15, Customer Analysis projection table ($100M/yr federal demand assumption, 40-65% capture, state/local $10M-$30M).
A25: Volume arrives in lumps: FY2026 civilian MAS obligations were $98.6M; FY2016-FY2017 were zero.

Sheet Claims Check
A1: Claims in the source documents, checked against the data
A3: Source | B3: Claim | C3: Verdict | D3: What the data shows | E3: Tab
A4: GSS memo, Sep 2025 | B4: CBP is 70% of civilian helicopter purchasing | C4: Holds | D4: 70% of aircraft with known counts (42 of 60); 63% of purchase dollars | E4: Summary, Purchases
A5: GSS memo, Sep 2025 | B5: DOJ buys Bell helicopters | C5: Holds | D5: FBI five Bell 429s; DEA Bell 407s new and used; $55.2M combined | E5: Buyers & Competition
A6: GSS memo, Sep 2025 | B6: State is an active helicopter buyer | C6: Not supported | D6: One used Bell 206B3 ($0.8M). State's other PSC 1520 spend is depot maintenance of partner-nation aircraft | E6: Purchases
A7: GSS memo, Sep 2025 | B7: State and local demand is limited | C7: Not supported | D7: $63M-$113M in state/local sales on the contract, FY2020-FY2026 Q2 (22-38% of sales) | E7: Contract Sales
A8: GSS memo, Sep 2025 | B8: CBP previously sourced helicopters directly from Airbus | C8: No evidence | D8: No CBP purchase direct from Airbus in FY2016-FY2026 FPDS; all five CBP orders went to Davenport on MAS | E8: CBP Orders
A9: GSS memo, Sep 2025 | B9: Open-market competition among Airbus resellers would yield better pricing | C9: No evidence | D9: No open-market purchase of a configured H125 exists to compare. The May 2026 MAS order drew two bids | E9: CBP Orders
A10: GSS memo, Sep 2025 | B10: MAS creates a near sole-source environment | C10: Partly | D10: Four of five CBP orders drew one offer. Cause is the brand-name requirement and one reseller on schedule | E10: CBP Orders
A11: Change package | B11: Helicopters were removed from MAS as low-demand | C11: Not supported | D11: $293.9M in sales FY2020-FY2026 Q2; $39.3M on SIN 336413 after the April 2025 exclusion | E11: Contract Sales
A12: Change package | B12: CBP bought 16 aircraft in 2020 | C12: Not supported | D12: FPDS shows two orders totaling 19 aircraft (Aug 2019 and Feb 2021-Sep 2022). 42 aircraft across five orders | E12: CBP Orders
A13: Change package | B13: Federal civilian demand of $100M/yr (10-15 aircraft) | C13: Not supported | D13: Purchases averaged $46M/yr and about 5.5 aircraft/yr, FY2016-FY2026 | E13: Annual Trends
A14: Change package | B14: SIN capture of federal demand starts at 40% | C14: Not supported | D14: MAS already carries 68% of federal civilian purchase dollars | E14: Buyers & Competition
... A20: RFI draft | B20: Agencies generally buy through agency-specific contracts, not MAS | C20: Not supported | D20: 68% of federal civilian purchase dollars went through MAS | E20: Buyers & Competition

Sheet Gaps & Sources
A1: Information gaps, method, and sources
A3: Missing input | B3: What it would settle | C3: How the workbook handles it
A4: Document creating the temporary accommodation, with effective date | B4: Whether CBP's Sep 2025 ($17.6M) and May 2026 ($95.5M) orders were in scope at award | C4: States the timing risk; recommends the PMO document the accommodation before approval
A5: Davenport confirmation of FY2025-FY2026 customer-type split | B5: Whether $49.2M reported as state/local was CBP deliveries | C5: Shows state/local as a range and leads with the low end (22% of sales)
A6: FAIRS helicopter counts, models, and ages | B6: Fleet replacement demand | C6: Uses observed purchases (~5.5 aircraft/yr) instead of an inventory estimate
A7: LESO/1033 aircraft holdings | B7: Size and timing of state/local replacement demand | C7: Described qualitatively; no projection figure depends on it
A8: Full eLibrary listing of SIN 336413 holders | B8: Whether any other MAS contractor lists complete aircraft | C8: FPDS and SSQ+ show no other seller of complete aircraft
A9: GSS memo's supporting Google Doc | B9: The data behind the Sep 2025 conclusions | C9: Memo claims checked directly against FPDS and SSQ+ (Claims Check tab)
A12: Method
A13: FPDS: USAspending prime award transactions for PSC 1520, NAICS 336411 (helicopter descriptions only), and PSCs 1510/1560 with helicopter keywords, FY2016-FY2026. Pulled Oct 19, 2026.
A14: Purchases: complete aircraft hand-tagged from award descriptions; sustainment, parts, overhaul, and the Coast Guard H-60 hull rebuild excluded. Customer = funding agency.
A15: CBP orders: every action under GS-07F-139DA from the USAspending IDV child-award endpoint; aircraft counts from modification text and press releases (CBP Orders tab, column K).
A16: Contract sales: SSQ+ (Schedule Sales Query Plus), GS-07F-139DA, by SIN and customer type, FY2017 Q2 to FY2026 Q2.
A17: Adjacent spend: helicopter-keyword pulls of V1xx, J01x, K01x, and parts PSCs. Floors, not totals.
A18: FY2026 is incomplete in FPDS and SSQ+. DoD data runs about 90 days behind.
A19: Color key: blue text = hard-coded input; yellow fill = assumption to vary; green = cross-tab link; black = formula.
A21: Sources
A22: USAspending.gov prime award transactions and IDV child awards (pulled Oct 19, 2026)
A23: GSA SSQ+ Schedule Sales Query Plus, GS-07F-139DA
A24: GSA MAS Refresh 26 SF30 attachment, solicitation 47QSMD20R0001 (Apr 25, 2025)
... A34: GAMA 2025 aircraft shipment and billing report
